Workbook

Sheet Consolidado_Unicos
A1: INVITACIÓN | B1: CEDULA | C1: NOMBRE | D1: Nombre Nivel 2 | E1: Nombre Nivel 3 | F1: Descripción Cargo | G1: Nombre Centro Costo | H1: ESCUELA
A2: =IF(B2="","",IFERROR(VLOOKUP(B2, PLANTA_BASE!A:R, 2, FALSE), "NO ENCONTRADO EN PLANTA")) | B2: 80812606 | C2: SANDINO MARTINEZ MIGUEL ERNESTO | D2: =IF(B2="","",IFERROR(VLOOKUP(B2, PLANTA_BASE!A:R, 5, FALSE), "NO ENCONTRADO EN PLANTA")) | E2: =IF(B2="","",IFERROR(VLOOKUP(B2, PLANTA_BASE!A:R, 6, FALSE), "NO ENCONTRADO EN PLANTA")) | F2: =IF(B2="","",IFERROR(VLOOKUP(B2, PLANTA_BASE!A:R, 8, FALSE), "DOCENTE / FACILITADOR")) | G2: =IF(B2="","",IFERROR(VLOOKUP(B2, PLANTA_BASE!A:R, 9, FALSE), "GENERAL")) | H2: =IF(B2="","",IFERROR(VLOOKUP(B2, PLANTA_BASE!A:R, 17, FALSE), "GENERAL"))
A3: =IF(B3="","",IFERROR(VLOOKUP(B3, PLANTA_BASE!A:R, 2, FALSE), "NO ENCONTRADO EN PLANTA")) | B3: 1015412447 | C3: GARCIA JUAN SEBASTIAN | D3: =IF(B3="","",IFERROR(VLOOKUP(B3, PLANTA_BASE!A:R, 5, FALSE), "NO ENCONTRADO EN PLANTA")) | E3: =IF(B3="","",IFERROR(VLOOKUP(B3, PLANTA_BASE!A:R, 6, FALSE), "NO ENCONTRADO EN PLANTA")) | F3: =IF(B3="","",IFERROR(VLOOKUP(B3, PLANTA_BASE!A:R, 8, FALSE), "DOCENTE / FACILITADOR")) | G3: =IF(B3="","",IFERROR(VLOOKUP(B3, PLANTA_BASE!A:R, 9, FALSE), "GENERAL")) | H3: =IF(B3="","",IFERROR(VLOOKUP(B3, PLANTA_BASE!A:R, 17, FALSE), "GENERAL"))
A4: =IF(B4="","",IFERROR(VLOOKUP(B4, PLANTA_BASE!A:R, 2, FALSE), "NO ENCONTRADO EN PLANTA")) | B4: 1233504005 | C4: BUITRAGO SANTIAGO | D4: =IF(B4="","",IFERROR(VLOOKUP(B4, PLANTA_BASE!A:R, 5, FALSE), "NO ENCONTRADO EN PLANTA")) | E4: =IF(B4="","",IFERROR(VLOOKUP(B4, PLANTA_BASE!A:R, 6, FALSE), "NO ENCONTRADO EN PLANTA")) | F4: =IF(B4="","",IFERROR(VLOOKUP(B4, PLANTA_BASE!A:R, 8, FALSE), "DOCENTE / FACILITADOR")) | G4: =IF(B4="","",IFERROR(VLOOKUP(B4, PLANTA_BASE!A:R, 9, FALSE), "GENERAL")) | H4: =IF(B4="","",IFERROR(VLOOKUP(B4, PLANTA_BASE!A:R, 17, FALSE), "GENERAL"))
A5: =IF(B5="","",IFERROR(VLOOKUP(B5, PLANTA_BASE!A:R, 2, FALSE), "NO ENCONTRADO EN PLANTA")) | B5: 1023885019 | C5: VELEZ JESUS | D5: =IF(B5="","",IFERROR(VLOOKUP(B5, PLANTA_BASE!A:R, 5, FALSE), "NO ENCONTRADO EN PLANTA")) | E5: =IF(B5="","",IFERROR(VLOOKUP(B5, PLANTA_BASE!A:R, 6, FALSE), "NO ENCONTRADO EN PLANTA")) | F5: =IF(B5="","",IFERROR(VLOOKUP(B5, PLANTA_BASE!A:R, 8, FALSE), "DOCENTE / FACILITADOR")) | G5: =IF(B5="","",IFERROR(VLOOKUP(B5, PLANTA_BASE!A:R, 9, FALSE), "GENERAL")) | H5: =IF(B5="","",IFERROR(VLOOKUP(B5, PLANTA_BASE!A:R, 17, FALSE), "GENERAL"))
A6: =IF(B6="","",IFERROR(VLOOKUP(B6, PLANTA_BASE!A:R, 2, FALSE), "NO ENCONTRADO EN PLANTA")) | B6: 80793106 | C6: RINCON ENRIQUE | D6: =IF(B6="","",IFERROR(VLOOKUP(B6, PLANTA_BASE!A:R, 5, FALSE), "NO ENCONTRADO EN PLANTA")) | E6: =IF(B6="","",IFERROR(VLOOKUP(B6, PLANTA_BASE!A:R, 6, FALSE), "NO ENCONTRADO EN PLANTA")) | F6: =IF(B6="","",IFERROR(VLOOKUP(B6, PLANTA_BASE!A:R, 8, FALSE), "DOCENTE / FACILITADOR")) | G6: =IF(B6="","",IFERROR(VLOOKUP(B6, PLANTA_BASE!A:R, 9, FALSE), "GENERAL")) | H6: =IF(B6="","",IFERROR(VLOOKUP(B6, PLANTA_BASE!A:R, 17, FALSE), "GENERAL"))
A7: =IF(B7="","",IFERROR(VLOOKUP(B7, PLANTA_BASE!A:R, 2, FALSE), "NO ENCONTRADO EN PLANTA")) | B7: 1070961899 | C7: AREVALO FELIPE | D7: =IF(B7="","",IFERROR(VLOOKUP(B7, PLANTA_BASE!A:R, 5, FALSE), "NO ENCONTRADO EN PLANTA")) | E7: =IF(B7="","",IFERROR(VLOOKUP(B7, PLANTA_BASE!A:R, 6, FALSE), "NO ENCONTRADO EN PLANTA")) | F7: =IF(B7="","",IFERROR(VLOOKUP(B7, PLANTA_BASE!A:R, 8, FALSE), "DOCENTE / FACILITADOR")) | G7: =IF(B7="","",IFERROR(VLOOKUP(B7, PLANTA_BASE!A:R, 9, FALSE), "GENERAL")) | H7: =IF(B7="","",IFERROR(VLOOKUP(B7, PLANTA_BASE!A:R, 17, FALSE), "GENERAL"))
A8: =IF(B8="","",IFERROR(VLOOKUP(B8, PLANTA_BASE!A:R, 2, FALSE), "NO ENCONTRADO EN PLANTA")) | B8: 1010201839 | C8: BECERRA ALEJANDRO | D8: =IF(B8="","",IFERROR(VLOOKUP(B8, PLANTA_BASE!A:R, 5, FALSE), "NO ENCONTRADO EN PLANTA")) | E8: =IF(B8="","",IFERROR(VLOOKUP(B8, PLANTA_BASE!A:R, 6, FALSE), "NO ENCONTRADO EN PLANTA")) | F8: =IF(B8="","",IFERROR(VLOOKUP(B8, PLANTA_BASE!A:R, 8, FALSE), "DOCENTE / FACILITADOR")) | G8: =IF(B8="","",IFERROR(VLOOKUP(B8, PLANTA_BASE!A:R, 9, FALSE), "GENERAL")) | H8: =IF(B8="","",IFERROR(VLOOKUP(B8, PLANTA_BASE!A:R, 17, FALSE), "GENERAL"))
A9: =IF(B9="","",IFERROR(VLOOKUP(B9, PLANTA_BASE!A:R, 2, FALSE), "NO ENCONTRADO EN PLANTA")) | B9: 1010227949 | C9: PAEZ BALAGUERA HENRY ALEJANDRO | D9: =IF(B9="","",IFERROR(VLOOKUP(B9, PLANTA_BASE!A:R, 5, FALSE), "NO ENCONTRADO EN PLANTA")) | E9: =IF(B9="","",IFERROR(VLOOKUP(B9, PLANTA_BASE!A:R, 6, FALSE), "NO ENCONTRADO EN PLANTA")) | F9: =IF(B9="","",IFERROR(VLOOKUP(B9, PLANTA_BASE!A:R, 8, FALSE), "DOCENTE / FACILITADOR")) | G9: =IF(B9="","",IFERROR(VLOOKUP(B9, PLANTA_BASE!A:R, 9, FALSE), "GENERAL")) | H9: =IF(B9="","",IFERROR(VLOOKUP(B9, PLANTA_BASE!A:R, 17, FALSE), "GENERAL"))
A10: =IF(B10="","",IFERROR(VLOOKUP(B10, PLANTA_BASE!A:R, 2, FALSE), "NO ENCONTRADO EN PLANTA")) | B10: 52973771 | C10: CASTRO ARDILA AMALIA | D10: =IF(B10="","",IFERROR(VLOOKUP(B10, PLANTA_BASE!A:R, 5, FALSE), "NO ENCONTRADO EN PLANTA")) | E10: =IF(B10="","",IFERROR(VLOOKUP(B10, PLANTA_BASE!A:R, 6, FALSE), "NO ENCONTRADO EN PLANTA")) | F10: =IF(B10="","",IFERROR(VLOOKUP(B10, PLANTA_BASE!A:R, 8, FALSE), "DOCENTE / FACILITADOR")) | G10: =IF(B10="","",IFERROR(VLOOKUP(B10, PLANTA_BASE!A:R, 9, FALSE), "GENERAL")) | H10: =IF(B10="","",IFERROR(VLOOKUP(B10, PLANTA_BASE!A:R, 17, FALSE), "GENERAL"))
A11: =IF(B11="","",IFERROR(VLOOKUP(B11, PLANTA_BASE!A:R, 2, FALSE), "NO ENCONTRADO EN PLANTA")) | B11: 1010131353 | C11: BARBOSA VARGAS MIGUEL ANGEL | D11: =IF(B11="","",IFERROR(VLOOKUP(B11, PLANTA_BASE!A:R, 5, FALSE), "NO ENCONTRADO EN PLANTA")) | E11: =IF(B11="","",IFERROR(VLOOKUP(B11, PLANTA_BASE!A:R, 6, FALSE), "NO ENCONTRADO EN PLANTA")) | F11: =IF(B11="","",IFERROR(VLOOKUP(B11, PLANTA_BASE!A:R, 8, FALSE), "DOCENTE / FACILITADOR")) | G11: =IF(B11="","",IFERROR(VLOOKUP(B11, PLANTA_BASE!A:R, 9, FALSE), "GENERAL")) | H11: =IF(B11="","",IFERROR(VLOOKUP(B11, PLANTA_BASE!A:R, 17, FALSE), "GENERAL"))
A12: =IF(B12="","",IFERROR(VLOOKUP(B12, PLANTA_BASE!A:R, 2, FALSE), "NO ENCONTRADO EN PLANTA")) | B12: 79802019 | C12: LANCHEROS N LUIS GABRIEL | D12: =IF(B12="","",IFERROR(VLOOKUP(B12, PLANTA_BASE!A:R, 5, FALSE), "NO ENCONTRADO EN PLANTA")) | E12: =IF(B12="","",IFERROR(VLOOKUP(B12, PLANTA_BASE!A:R, 6, FALSE), "NO ENCONTRADO EN PLANTA")) | F12: =IF(B12="","",IFERROR(VLOOKUP(B12, PLANTA_BASE!A:R, 8, FALSE), "DOCENTE / FACILITADOR")) | G12: =IF(B12="","",IFERROR(VLOOKUP(B12, PLANTA_BASE!A:R, 9, FALSE), "GENERAL")) | H12: =IF(B12="","",IFERROR(VLOOKUP(B12, PLANTA_BASE!A:R, 17, FALSE), "GENERAL"))
A13: =IF(B13="","",IFERROR(VLOOKUP(B13, PLANTA_BASE!A:R, 2, FALSE), "NO ENCONTRADO EN PLANTA")) | B13: 52869673 | C13: BARRERA LESLIE | D13: =IF(B13="","",IFERROR(VLOOKUP(B13, PLANTA_BASE!A:R, 5, FALSE), "NO ENCONTRADO EN PLANTA")) | E13: =IF(B13="","",IFERROR(VLOOKUP(B13, PLANTA_BASE!A:R, 6, FALSE), "NO ENCONTRADO EN PLANTA")) | F13: =IF(B13="","",IFERROR(VLOOKUP(B13, PLANTA_BASE!A:R, 8, FALSE), "DOCENTE / FACILITADOR")) | G13: =IF(B13="","",IFERROR(VLOOKUP(B13, PLANTA_BASE!A:R, 9, FALSE), "GENERAL")) | H13: =IF(B13="","",IFERROR(VLOOKUP(B13, PLANTA_BASE!A:R, 17, FALSE), "GENERAL"))
... A380: =IF(B380="","",IFERROR(VLOOKUP(B380, PLANTA_BASE!A:R, 2, FALSE), "NO ENCONTRADO EN PLANTA")) | B380: 80547263 | C380: FERRER MAYORGA JOHN ALEXANDER | D380: =IF(B380="","",IFERROR(VLOOKUP(B380, PLANTA_BASE!A:R, 5, FALSE), "NO ENCONTRADO EN PLANTA")) | E380: =IF(B380="","",IFERROR(VLOOKUP(B380, PLANTA_BASE!A:R, 6, FALSE), "NO ENCONTRADO EN PLANTA")) | F380: =IF(B380="","",IFERROR(VLOOKUP(B380, PLANTA_BASE!A:R, 8, FALSE), "DOCENTE / FACILITADOR")) | G380: =IF(B380="","",IFERROR(VLOOKUP(B380, PLANTA_BASE!A:R, 9, FALSE), "GENERAL")) | H380: =IF(B380="","",IFERROR(VLOOKUP(B380, PLANTA_BASE!A:R, 17, FALSE), "GENERAL"))
A381: =IF(B381="","",IFERROR(VLOOKUP(B381, PLANTA_BASE!A:R, 2, FALSE), "NO ENCONTRADO EN PLANTA")) | C381: =IF(B381="","",IFERROR(VLOOKUP(B381, PLANTA_BASE!A:R, 3, FALSE), "")) | D381: =IF(B381="","",IFERROR(VLOOKUP(B381, PLANTA_BASE!A:R, 5, FALSE), "NO ENCONTRADO EN PLANTA")) | E381: =IF(B381="","",IFERROR(VLOOKUP(B381, PLANTA_BASE!A:R, 6, FALSE), "NO ENCONTRADO EN PLANTA")) | F381: =IF(B381="","",IFERROR(VLOOKUP(B381, PLANTA_BASE!A:R, 8, FALSE), "DOCENTE / FACILITADOR")) | G381: =IF(B381="","",IFERROR(VLOOKUP(B381, PLANTA_BASE!A:R, 9, FALSE), "GENERAL")) | H381: =IF(B381="","",IFERROR(VLOOKUP(B381, PLANTA_BASE!A:R, 17, FALSE), "GENERAL"))
A382: =IF(B382="","",IFERROR(VLOOKUP(B382, PLANTA_BASE!A:R, 2, FALSE), "NO ENCONTRADO EN PLANTA")) | C382: =IF(B382="","",IFERROR(VLOOKUP(B382, PLANTA_BASE!A:R, 3, FALSE), "")) | D382: =IF(B382="","",IFERROR(VLOOKUP(B382, PLANTA_BASE!A:R, 5, FALSE), "NO ENCONTRADO EN PLANTA")) | E382: =IF(B382="","",IFERROR(VLOOKUP(B382, PLANTA_BASE!A:R, 6, FALSE), "NO ENCONTRADO EN PLANTA")) | F382: =IF(B382="","",IFERROR(VLOOKUP(B382, PLANTA_BASE!A:R, 8, FALSE), "DOCENTE / FACILITADOR")) | G382: =IF(B382="","",IFERROR(VLOOKUP(B382, PLANTA_BASE!A:R, 9, FALSE), "GENERAL")) | H382: =IF(B382="","",IFERROR(VLOOKUP(B382, PLANTA_BASE!A:R, 17, FALSE), "GENERAL"))
A383: =IF(B383="","",IFERROR(VLOOKUP(B383, PLANTA_BASE!A:R, 2, FALSE), "NO ENCONTRADO EN PLANTA")) | C383: =IF(B383="","",IFERROR(VLOOKUP(B383, PLANTA_BASE!A:R, 3, FALSE), "")) | D383: =IF(B383="","",IFERROR(VLOOKUP(B383, PLANTA_BASE!A:R, 5, FALSE), "NO ENCONTRADO EN PLANTA")) | E383: =IF(B383="","",IFERROR(VLOOKUP(B383, PLANTA_BASE!A:R, 6, FALSE), "NO ENCONTRADO EN PLANTA")) | F383: =IF(B383="","",IFERROR(VLOOKUP(B383, PLANTA_BASE!A:R, 8, FALSE), "DOCENTE / FACILITADOR")) | G383: =IF(B383="","",IFERROR(VLOOKUP(B383, PLANTA_BASE!A:R, 9, FALSE), "GENERAL")) | H383: =IF(B383="","",IFERROR(VLOOKUP(B383, PLANTA_BASE!A:R, 17, FALSE), "GENERAL"))
A384: =IF(B384="","",IFERROR(VLOOKUP(B384, PLANTA_BASE!A:R, 2, FALSE), "NO ENCONTRADO EN PLANTA")) | C384: =IF(B384="","",IFERROR(VLOOKUP(B384, PLANTA_BASE!A:R, 3, FALSE), "")) | D384: =IF(B384="","",IFERROR(VLOOKUP(B384, PLANTA_BASE!A:R, 5, FALSE), "NO ENCONTRADO EN PLANTA")) | E384: =IF(B384="","",IFERROR(VLOOKUP(B384, PLANTA_BASE!A:R, 6, FALSE), "NO ENCONTRADO EN PLANTA")) | F384: =IF(B384="","",IFERROR(VLOOKUP(B384, PLANTA_BASE!A:R, 8, FALSE), "DOCENTE / FACILITADOR")) | G384: =IF(B384="","",IFERROR(VLOOKUP(B384, PLANTA_BASE!A:R, 9, FALSE), "GENERAL")) | H384: =IF(B384="","",IFERROR(VLOOKUP(B384, PLANTA_BASE!A:R, 17, FALSE), "GENERAL"))
A385: =IF(B385="","",IFERROR(VLOOKUP(B385, PLANTA_BASE!A:R, 2, FALSE), "NO ENCONTRADO EN PLANTA")) | C385: =IF(B385="","",IFERROR(VLOOKUP(B385, PLANTA_BASE!A:R, 3, FALSE), "")) | D385: =IF(B385="","",IFERROR(VLOOKUP(B385, PLANTA_BASE!A:R, 5, FALSE), "NO ENCONTRADO EN PLANTA")) | E385: =IF(B385="","",IFERROR(VLOOKUP(B385, PLANTA_BASE!A:R, 6, FALSE), "NO ENCONTRADO EN PLANTA")) | F385: =IF(B385="","",IFERROR(VLOOKUP(B385, PLANTA_BASE!A:R, 8, FALSE), "DOCENTE / FACILITADOR")) | G385: =IF(B385="","",IFERROR(VLOOKUP(B385, PLANTA_BASE!A:R, 9, FALSE), "GENERAL")) | H385: =IF(B385="","",IFERROR(VLOOKUP(B385, PLANTA_BASE!A:R, 17, FALSE), "GENERAL"))
A386: =IF(B386="","",IFERROR(VLOOKUP(B386, PLANTA_BASE!A:R, 2, FALSE), "NO ENCONTRADO EN PLANTA")) | C386: =IF(B386="","",IFERROR(VLOOKUP(B386, PLANTA_BASE!A:R, 3, FALSE), "")) | D386: =IF(B386="","",IFERROR(VLOOKUP(B386, PLANTA_BASE!A:R, 5, FALSE), "NO ENCONTRADO EN PLANTA")) | E386: =IF(B386="","",IFERROR(VLOOKUP(B386, PLANTA_BASE!A:R, 6, FALSE), "NO ENCONTRADO EN PLANTA")) | F386: =IF(B386="","",IFERROR(VLOOKUP(B386, PLANTA_BASE!A:R, 8, FALSE), "DOCENTE / FACILITADOR")) | G386: =IF(B386="","",IFERROR(VLOOKUP(B386, PLANTA_BASE!A:R, 9, FALSE), "GENERAL")) | H386: =IF(B386="","",IFERROR(VLOOKUP(B386, PLANTA_BASE!A:R, 17, FALSE), "GENERAL"))
A387: =IF(B387="","",IFERROR(VLOOKUP(B387, PLANTA_BASE!A:R, 2, FALSE), "NO ENCONTRADO EN PLANTA")) | C387: =IF(B387="","",IFERROR(VLOOKUP(B387, PLANTA_BASE!A:R, 3, FALSE), "")) | D387: =IF(B387="","",IFERROR(VLOOKUP(B387, PLANTA_BASE!A:R, 5, FALSE), "NO ENCONTRADO EN PLANTA")) | E387: =IF(B387="","",IFERROR(VLOOKUP(B387, PLANTA_BASE!A:R, 6, FALSE), "NO ENCONTRADO EN PLANTA")) | F387: =IF(B387="","",IFERROR(VLOOKUP(B387, PLANTA_BASE!A:R, 8, FALSE), "DOCENTE / FACILITADOR")) | G387: =IF(B387="","",IFERROR(VLOOKUP(B387, PLANTA_BASE!A:R, 9, FALSE), "GENERAL")) | H387: =IF(B387="","",IFERROR(VLOOKUP(B387, PLANTA_BASE!A:R, 17, FALSE), "GENERAL"))
A388: =IF(B388="","",IFERROR(VLOOKUP(B388, PLANTA_BASE!A:R, 2, FALSE), "NO ENCONTRADO EN PLANTA")) | C388: =IF(B388="","",IFERROR(VLOOKUP(B388, PLANTA_BASE!A:R, 3, FALSE), "")) | D388: =IF(B388="","",IFERROR(VLOOKUP(B388, PLANTA_BASE!A:R, 5, FALSE), "NO ENCONTRADO EN PLANTA")) | E388: =IF(B388="","",IFERROR(VLOOKUP(B388, PLANTA_BASE!A:R, 6, FALSE), "NO ENCONTRADO EN PLANTA")) | F388: =IF(B388="","",IFERROR(VLOOKUP(B388, PLANTA_BASE!A:R, 8, FALSE), "DOCENTE / FACILITADOR")) | G388: =IF(B388="","",IFERROR(VLOOKUP(B388, PLANTA_BASE!A:R, 9, FALSE), "GENERAL")) | H388: =IF(B388="","",IFERROR(VLOOKUP(B388, PLANTA_BASE!A:R, 17, FALSE), "GENERAL"))
A389: =IF(B389="","",IFERROR(VLOOKUP(B389, PLANTA_BASE!A:R, 2, FALSE), "NO ENCONTRADO EN PLANTA")) | C389: =IF(B389="","",IFERROR(VLOOKUP(B389, PLANTA_BASE!A:R, 3, FALSE), "")) | D389: =IF(B389="","",IFERROR(VLOOKUP(B389, PLANTA_BASE!A:R, 5, FALSE), "NO ENCONTRADO EN PLANTA")) | E389: =IF(B389="","",IFERROR(VLOOKUP(B389, PLANTA_BASE!A:R, 6, FALSE), "NO ENCONTRADO EN PLANTA")) | F389: =IF(B389="","",IFERROR(VLOOKUP(B389, PLANTA_BASE!A:R, 8, FALSE), "DOCENTE / FACILITADOR")) | G389: =IF(B389="","",IFERROR(VLOOKUP(B389, PLANTA_BASE!A:R, 9, FALSE), "GENERAL")) | H389: =IF(B389="","",IFERROR(VLOOKUP(B389, PLANTA_BASE!A:R, 17, FALSE), "GENERAL"))
A390: =IF(B390="","",IFERROR(VLOOKUP(B390, PLANTA_BASE!A:R, 2, FALSE), "NO ENCONTRADO EN PLANTA")) | C390: =IF(B390="","",IFERROR(VLOOKUP(B390, PLANTA_BASE!A:R, 3, FALSE), "")) | D390: =IF(B390="","",IFERROR(VLOOKUP(B390, PLANTA_BASE!A:R, 5, FALSE), "NO ENCONTRADO EN PLANTA")) | E390: =IF(B390="","",IFERROR(VLOOKUP(B390, PLANTA_BASE!A:R, 6, FALSE), "NO ENCONTRADO EN PLANTA")) | F390: =IF(B390="","",IFERROR(VLOOKUP(B390, PLANTA_BASE!A:R, 8, FALSE), "DOCENTE / FACILITADOR")) | G390: =IF(B390="","",IFERROR(VLOOKUP(B390, PLANTA_BASE!A:R, 9, FALSE), "GENERAL")) | H390: =IF(B390="","",IFERROR(VLOOKUP(B390, PLANTA_BASE!A:R, 17, FALSE), "GENERAL"))
A391: =IF(B391="","",IFERROR(VLOOKUP(B391, PLANTA_BASE!A:R, 2, FALSE), "NO ENCONTRADO EN PLANTA")) | C391: =IF(B391="","",IFERROR(VLOOKUP(B391, PLANTA_BASE!A:R, 3, FALSE), "")) | D391: =IF(B391="","",IFERROR(VLOOKUP(B391, PLANTA_BASE!A:R, 5, FALSE), "NO ENCONTRADO EN PLANTA")) | E391: =IF(B391="","",IFERROR(VLOOKUP(B391, PLANTA_BASE!A:R, 6, FALSE), "NO ENCONTRADO EN PLANTA")) | F391: =IF(B391="","",IFERROR(VLOOKUP(B391, PLANTA_BASE!A:R, 8, FALSE), "DOCENTE / FACILITADOR")) | G391: =IF(B391="","",IFERROR(VLOOKUP(B391, PLANTA_BASE!A:R, 9, FALSE), "GENERAL")) | H391: =IF(B391="","",IFERROR(VLOOKUP(B391, PLANTA_BASE!A:R, 17, FALSE), "GENERAL"))
A392: =IF(B392="","",IFERROR(VLOOKUP(B392, PLANTA_BASE!A:R, 2, FALSE), "NO ENCONTRADO EN PLANTA")) | C392: =IF(B392="","",IFERROR(VLOOKUP(B392, PLANTA_BASE!A:R, 3, FALSE), "")) | D392: =IF(B392="","",IFERROR(VLOOKUP(B392, PLANTA_BASE!A:R, 5, FALSE), "NO ENCONTRADO EN PLANTA")) | E392: =IF(B392="","",IFERROR(VLOOKUP(B392, PLANTA_BASE!A:R, 6, FALSE), "NO ENCONTRADO EN PLANTA")) | F392: =IF(B392="","",IFERROR(VLOOKUP(B392, PLANTA_BASE!A:R, 8, FALSE), "DOCENTE / FACILITADOR")) | G392: =IF(B392="","",IFERROR(VLOOKUP(B392, PLANTA_BASE!A:R, 9, FALSE), "GENERAL")) | H392: =IF(B392="","",IFERROR(VLOOKUP(B392, PLANTA_BASE!A:R, 17, FALSE), "GENERAL"))
... A1501: =IF(B1501="","",IFERROR(VLOOKUP(B1501, PLANTA_BASE!A:R, 2, FALSE), "NO ENCONTRADO EN PLANTA")) | C1501: =IF(B1501="","",IFERROR(VLOOKUP(B1501, PLANTA_BASE!A:R, 3, FALSE), "")) | D1501: =IF(B1501="","",IFERROR(VLOOKUP(B1501, PLANTA_BASE!A:R, 5, FALSE), "NO ENCONTRADO EN PLANTA")) | E1501: =IF(B1501="","",IFERROR(VLOOKUP(B1501, PLANTA_BASE!A:R, 6, FALSE), "NO ENCONTRADO EN PLANTA")) | F1501: =IF(B1501="","",IFERROR(VLOOKUP(B1501, PLANTA_BASE!A:R, 8, FALSE), "DOCENTE / FACILITADOR")) | G1501: =IF(B1501="","",IFERROR(VLOOKUP(B1501, PLANTA_BASE!A:R, 9, FALSE), "GENERAL")) | H1501: =IF(B1501="","",IFERROR(VLOOKUP(B1501, PLANTA_BASE!A:R, 17, FALSE), "GENERAL"))

Sheet Duplicados
A1: INVITACIÓN | B1: CEDULA | C1: NOMBRE | D1: Nombre Nivel 2 | E1: Nombre Nivel 3 | F1: Descripción Cargo | G1: Nombre Centro Costo | H1: ESCUELA
A2: =IF(B2="","",IFERROR(VLOOKUP(B2, PLANTA_BASE!A:R, 2, FALSE), "NO ENCONTRADO EN PLANTA")) | B2: 80812606 | C2: SANDINO MARTINEZ MIGUEL ERNESTO | D2: =IF(B2="","",IFERROR(VLOOKUP(B2, PLANTA_BASE!A:R, 5, FALSE), "NO ENCONTRADO EN PLANTA")) | E2: =IF(B2="","",IFERROR(VLOOKUP(B2, PLANTA_BASE!A:R, 6, FALSE), "NO ENCONTRADO EN PLANTA")) | F2: =IF(B2="","",IFERROR(VLOOKUP(B2, PLANTA_BASE!A:R, 8, FALSE), "DOCENTE / FACILITADOR")) | G2: =IF(B2="","",IFERROR(VLOOKUP(B2, PLANTA_BASE!A:R, 9, FALSE), "GENERAL")) | H2: =IF(B2="","",IFERROR(VLOOKUP(B2, PLANTA_BASE!A:R, 17, FALSE), "GENERAL"))
A3: =IF(B3="","",IFERROR(VLOOKUP(B3, PLANTA_BASE!A:R, 2, FALSE), "NO ENCONTRADO EN PLANTA")) | B3: 38285304 | C3: ALFONSO OERIZ QDRIANA DEL ROCIO | D3: =IF(B3="","",IFERROR(VLOOKUP(B3, PLANTA_BASE!A:R, 5, FALSE), "NO ENCONTRADO EN PLANTA")) | E3: =IF(B3="","",IFERROR(VLOOKUP(B3, PLANTA_BASE!A:R, 6, FALSE), "NO ENCONTRADO EN PLANTA")) | F3: =IF(B3="","",IFERROR(VLOOKUP(B3, PLANTA_BASE!A:R, 8, FALSE), "DOCENTE / FACILITADOR")) | G3: =IF(B3="","",IFERROR(VLOOKUP(B3, PLANTA_BASE!A:R, 9, FALSE), "GENERAL")) | H3: =IF(B3="","",IFERROR(VLOOKUP(B3, PLANTA_BASE!A:R, 17, FALSE), "GENERAL"))
A4: =IF(B4="","",IFERROR(VLOOKUP(B4, PLANTA_BASE!A:R, 2, FALSE), "NO ENCONTRADO EN PLANTA")) | B4: 722264339 | C4: MARBELLO HENAO YURY ALEXANDER | D4: =IF(B4="","",IFERROR(VLOOKUP(B4, PLANTA_BASE!A:R, 5, FALSE), "NO ENCONTRADO EN PLANTA")) | E4: =IF(B4="","",IFERROR(VLOOKUP(B4, PLANTA_BASE!A:R, 6, FALSE), "NO ENCONTRADO EN PLANTA")) | F4: =IF(B4="","",IFERROR(VLOOKUP(B4, PLANTA_BASE!A:R, 8, FALSE), "DOCENTE / FACILITADOR")) | G4: =IF(B4="","",IFERROR(VLOOKUP(B4, PLANTA_BASE!A:R, 9, FALSE), "GENERAL")) | H4: =IF(B4="","",IFERROR(VLOOKUP(B4, PLANTA_BASE!A:R, 17, FALSE), "GENERAL"))
A5: =IF(B5="","",IFERROR(VLOOKUP(B5, PLANTA_BASE!A:R, 2, FALSE), "NO ENCONTRADO EN PLANTA")) | B5: 79922635 | C5: NECHIZA MILTON RAMIRO | D5: =IF(B5="","",IFERROR(VLOOKUP(B5, PLANTA_BASE!A:R, 5, FALSE), "NO ENCONTRADO EN PLANTA")) | E5: =IF(B5="","",IFERROR(VLOOKUP(B5, PLANTA_BASE!A:R, 6, FALSE), "NO ENCONTRADO EN PLANTA")) | F5: =IF(B5="","",IFERROR(VLOOKUP(B5, PLANTA_BASE!A:R, 8, FALSE), "DOCENTE / FACILITADOR")) | G5: =IF(B5="","",IFERROR(VLOOKUP(B5, PLANTA_BASE!A:R, 9, FALSE), "GENERAL")) | H5: =IF(B5="","",IFERROR(VLOOKUP(B5, PLANTA_BASE!A:R, 17, FALSE), "GENERAL"))
A6: =IF(B6="","",IFERROR(VLOOKUP(B6, PLANTA_BASE!A:R, 2, FALSE), "NO ENCONTRADO EN PLANTA")) | B6: 1032461201 | C6: BARRETO TORRES MARLEY GISEL | D6: =IF(B6="","",IFERROR(VLOOKUP(B6, PLANTA_BASE!A:R, 5, FALSE), "NO ENCONTRADO EN PLANTA")) | E6: =IF(B6="","",IFERROR(VLOOKUP(B6, PLANTA_BASE!A:R, 6, FALSE), "NO ENCONTRADO EN PLANTA")) | F6: =IF(B6="","",IFERROR(VLOOKUP(B6, PLANTA_BASE!A:R, 8, FALSE), "DOCENTE / FACILITADOR")) | G6: =IF(B6="","",IFERROR(VLOOKUP(B6, PLANTA_BASE!A:R, 9, FALSE), "GENERAL")) | H6: =IF(B6="","",IFERROR(VLOOKUP(B6, PLANTA_BASE!A:R, 17, FALSE), "GENERAL"))
A7: =IF(B7="","",IFERROR(VLOOKUP(B7, PLANTA_BASE!A:R, 2, FALSE), "NO ENCONTRADO EN PLANTA")) | B7: 80223287 | C7: PINEDA SORIANO MARIO ALBERTO | D7: =IF(B7="","",IFERROR(VLOOKUP(B7, PLANTA_BASE!A:R, 5, FALSE), "NO ENCONTRADO EN PLANTA")) | E7: =IF(B7="","",IFERROR(VLOOKUP(B7, PLANTA_BASE!A:R, 6, FALSE), "NO ENCONTRADO EN PLANTA")) | F7: =IF(B7="","",IFERROR(VLOOKUP(B7, PLANTA_BASE!A:R, 8, FALSE), "DOCENTE / FACILITADOR")) | G7: =IF(B7="","",IFERROR(VLOOKUP(B7, PLANTA_BASE!A:R, 9, FALSE), "GENERAL")) | H7: =IF(B7="","",IFERROR(VLOOKUP(B7, PLANTA_BASE!A:R, 17, FALSE), "GENERAL"))
A8: =IF(B8="","",IFERROR(VLOOKUP(B8, PLANTA_BASE!A:R, 2, FALSE), "NO ENCONTRADO EN PLANTA")) | B8: 102451434 | C8: ARIAS MORENO JORGE LEONARDO | D8: =IF(B8="","",IFERROR(VLOOKUP(B8, PLANTA_BASE!A:R, 5, FALSE), "NO ENCONTRADO EN PLANTA")) | E8: =IF(B8="","",IFERROR(VLOOKUP(B8, PLANTA_BASE!A:R, 6, FALSE), "NO ENCONTRADO EN PLANTA")) | F8: =IF(B8="","",IFERROR(VLOOKUP(B8, PLANTA_BASE!A:R, 8, FALSE), "DOCENTE / FACILITADOR")) | G8: =IF(B8="","",IFERROR(VLOOKUP(B8, PLANTA_BASE!A:R, 9, FALSE), "GENERAL")) | H8: =IF(B8="","",IFERROR(VLOOKUP(B8, PLANTA_BASE!A:R, 17, FALSE), "GENERAL"))
A9: =IF(B9="","",IFERROR(VLOOKUP(B9, PLANTA_BASE!A:R, 2, FALSE), "NO ENCONTRADO EN PLANTA")) | B9: 80882570 | C9: GARRIDO ANDRES | D9: =IF(B9="","",IFERROR(VLOOKUP(B9, PLANTA_BASE!A:R, 5, FALSE), "NO ENCONTRADO EN PLANTA")) | E9: =IF(B9="","",IFERROR(VLOOKUP(B9, PLANTA_BASE!A:R, 6, FALSE), "NO ENCONTRADO EN PLANTA")) | F9: =IF(B9="","",IFERROR(VLOOKUP(B9, PLANTA_BASE!A:R, 8, FALSE), "DOCENTE / FACILITADOR")) | G9: =IF(B9="","",IFERROR(VLOOKUP(B9, PLANTA_BASE!A:R, 9, FALSE), "GENERAL")) | H9: =IF(B9="","",IFERROR(VLOOKUP(B9, PLANTA_BASE!A:R, 17, FALSE), "GENERAL"))
A10: =IF(B10="","",IFERROR(VLOOKUP(B10, PLANTA_BASE!A:R, 2, FALSE), "NO ENCONTRADO EN PLANTA")) | B10: 1054093212 | C10: PINILLA PARDO ROGGER FABIAN | D10: =IF(B10="","",IFERROR(VLOOKUP(B10, PLANTA_BASE!A:R, 5, FALSE), "NO ENCONTRADO EN PLANTA")) | E10: =IF(B10="","",IFERROR(VLOOKUP(B10, PLANTA_BASE!A:R, 6, FALSE), "NO ENCONTRADO EN PLANTA")) | F10: =IF(B10="","",IFERROR(VLOOKUP(B10, PLANTA_BASE!A:R, 8, FALSE), "DOCENTE / FACILITADOR")) | G10: =IF(B10="","",IFERROR(VLOOKUP(B10, PLANTA_BASE!A:R, 9, FALSE), "GENERAL")) | H10: =IF(B10="","",IFERROR(VLOOKUP(B10, PLANTA_BASE!A:R, 17, FALSE), "GENERAL"))
A11: =IF(B11="","",IFERROR(VLOOKUP(B11, PLANTA_BASE!A:R, 2, FALSE), "NO ENCONTRADO EN PLANTA")) | B11: 1005163088 | C11: ESCOBAR DYLAN | D11: =IF(B11="","",IFERROR(VLOOKUP(B11, PLANTA_BASE!A:R, 5, FALSE), "NO ENCONTRADO EN PLANTA")) | E11: =IF(B11="","",IFERROR(VLOOKUP(B11, PLANTA_BASE!A:R, 6, FALSE), "NO ENCONTRADO EN PLANTA")) | F11: =IF(B11="","",IFERROR(VLOOKUP(B11, PLANTA_BASE!A:R, 8, FALSE), "DOCENTE / FACILITADOR")) | G11: =IF(B11="","",IFERROR(VLOOKUP(B11, PLANTA_BASE!A:R, 9, FALSE), "GENERAL")) | H11: =IF(B11="","",IFERROR(VLOOKUP(B11, PLANTA_BASE!A:R, 17, FALSE), "GENERAL"))
A12: =IF(B12="","",IFERROR(VLOOKUP(B12, PLANTA_BASE!A:R, 2, FALSE), "NO ENCONTRADO EN PLANTA")) | B12: 1016015033 | C12: CASTELLANOS JUAN DAVID | D12: =IF(B12="","",IFERROR(VLOOKUP(B12, PLANTA_BASE!A:R, 5, FALSE), "NO ENCONTRADO EN PLANTA")) | E12: =IF(B12="","",IFERROR(VLOOKUP(B12, PLANTA_BASE!A:R, 6, FALSE), "NO ENCONTRADO EN PLANTA")) | F12: =IF(B12="","",IFERROR(VLOOKUP(B12, PLANTA_BASE!A:R, 8, FALSE), "DOCENTE / FACILITADOR")) | G12: =IF(B12="","",IFERROR(VLOOKUP(B12, PLANTA_BASE!A:R, 9, FALSE), "GENERAL")) | H12: =IF(B12="","",IFERROR(VLOOKUP(B12, PLANTA_BASE!A:R, 17, FALSE), "GENERAL"))
A13: =IF(B13="","",IFERROR(VLOOKUP(B13, PLANTA_BASE!A:R, 2, FALSE), "NO ENCONTRADO EN PLANTA")) | B13: 1023878064 | C13: ESTEPA NATALIA | D13: =IF(B13="","",IFERROR(VLOOKUP(B13, PLANTA_BASE!A:R, 5, FALSE), "NO ENCONTRADO EN PLANTA")) | E13: =IF(B13="","",IFERROR(VLOOKUP(B13, PLANTA_BASE!A:R, 6, FALSE), "NO ENCONTRADO EN PLANTA")) | F13: =IF(B13="","",IFERROR(VLOOKUP(B13, PLANTA_BASE!A:R, 8, FALSE), "DOCENTE / FACILITADOR")) | G13: =IF(B13="","",IFERROR(VLOOKUP(B13, PLANTA_BASE!A:R, 9, FALSE), "GENERAL")) | H13: =IF(B13="","",IFERROR(VLOOKUP(B13, PLANTA_BASE!A:R, 17, FALSE), "GENERAL"))
... A42: =IF(B42="","",IFERROR(VLOOKUP(B42, PLANTA_BASE!A:R, 2, FALSE), "NO ENCONTRADO EN PLANTA")) | B42: nan | C42: VARGAS CAMILO | D42: =IF(B42="","",IFERROR(VLOOKUP(B42, PLANTA_BASE!A:R, 5, FALSE), "NO ENCONTRADO EN PLANTA")) | E42: =IF(B42="","",IFERROR(VLOOKUP(B42, PLANTA_BASE!A:R, 6, FALSE), "NO ENCONTRADO EN PLANTA")) | F42: =IF(B42="","",IFERROR(VLOOKUP(B42, PLANTA_BASE!A:R, 8, FALSE), "DOCENTE / FACILITADOR")) | G42: =IF(B42="","",IFERROR(VLOOKUP(B42, PLANTA_BASE!A:R, 9, FALSE), "GENERAL")) | H42: =IF(B42="","",IFERROR(VLOOKUP(B42, PLANTA_BASE!A:R, 17, FALSE), "GENERAL"))
A43: =IF(B43="","",IFERROR(VLOOKUP(B43, PLANTA_BASE!A:R, 2, FALSE), "NO ENCONTRADO EN PLANTA")) | C43: =IF(B43="","",IFERROR(VLOOKUP(B43, PLANTA_BASE!A:R, 3, FALSE), "")) | D43: =IF(B43="","",IFERROR(VLOOKUP(B43, PLANTA_BASE!A:R, 5, FALSE), "NO ENCONTRADO EN PLANTA")) | E43: =IF(B43="","",IFERROR(VLOOKUP(B43, PLANTA_BASE!A:R, 6, FALSE), "NO ENCONTRADO EN PLANTA")) | F43: =IF(B43="","",IFERROR(VLOOKUP(B43, PLANTA_BASE!A:R, 8, FALSE), "DOCENTE / FACILITADOR")) | G43: =IF(B43="","",IFERROR(VLOOKUP(B43, PLANTA_BASE!A:R, 9, FALSE), "GENERAL")) | H43: =IF(B43="","",IFERROR(VLOOKUP(B43, PLANTA_BASE!A:R, 17, FALSE), "GENERAL"))
A44: =IF(B44="","",IFERROR(VLOOKUP(B44, PLANTA_BASE!A:R, 2, FALSE), "NO ENCONTRADO EN PLANTA")) | C44: =IF(B44="","",IFERROR(VLOOKUP(B44, PLANTA_BASE!A:R, 3, FALSE), "")) | D44: =IF(B44="","",IFERROR(VLOOKUP(B44, PLANTA_BASE!A:R, 5, FALSE), "NO ENCONTRADO EN PLANTA")) | E44: =IF(B44="","",IFERROR(VLOOKUP(B44, PLANTA_BASE!A:R, 6, FALSE), "NO ENCONTRADO EN PLANTA")) | F44: =IF(B44="","",IFERROR(VLOOKUP(B44, PLANTA_BASE!A:R, 8, FALSE), "DOCENTE / FACILITADOR")) | G44: =IF(B44="","",IFERROR(VLOOKUP(B44, PLANTA_BASE!A:R, 9, FALSE), "GENERAL")) | H44: =IF(B44="","",IFERROR(VLOOKUP(B44, PLANTA_BASE!A:R, 17, FALSE), "GENERAL"))
A45: =IF(B45="","",IFERROR(VLOOKUP(B45, PLANTA_BASE!A:R, 2, FALSE), "NO ENCONTRADO EN PLANTA")) | C45: =IF(B45="","",IFERROR(VLOOKUP(B45, PLANTA_BASE!A:R, 3, FALSE), "")) | D45: =IF(B45="","",IFERROR(VLOOKUP(B45, PLANTA_BASE!A:R, 5, FALSE), "NO ENCONTRADO EN PLANTA")) | E45: =IF(B45="","",IFERROR(VLOOKUP(B45, PLANTA_BASE!A:R, 6, FALSE), "NO ENCONTRADO EN PLANTA")) | F45: =IF(B45="","",IFERROR(VLOOKUP(B45, PLANTA_BASE!A:R, 8, FALSE), "DOCENTE / FACILITADOR")) | G45: =IF(B45="","",IFERROR(VLOOKUP(B45, PLANTA_BASE!A:R, 9, FALSE), "GENERAL")) | H45: =IF(B45="","",IFERROR(VLOOKUP(B45, PLANTA_BASE!A:R, 17, FALSE), "GENERAL"))
A46: =IF(B46="","",IFERROR(VLOOKUP(B46, PLANTA_BASE!A:R, 2, FALSE), "NO ENCONTRADO EN PLANTA")) | C46: =IF(B46="","",IFERROR(VLOOKUP(B46, PLANTA_BASE!A:R, 3, FALSE), "")) | D46: =IF(B46="","",IFERROR(VLOOKUP(B46, PLANTA_BASE!A:R, 5, FALSE), "NO ENCONTRADO EN PLANTA")) | E46: =IF(B46="","",IFERROR(VLOOKUP(B46, PLANTA_BASE!A:R, 6, FALSE), "NO ENCONTRADO EN PLANTA")) | F46: =IF(B46="","",IFERROR(VLOOKUP(B46, PLANTA_BASE!A:R, 8, FALSE), "DOCENTE / FACILITADOR")) | G46: =IF(B46="","",IFERROR(VLOOKUP(B46, PLANTA_BASE!A:R, 9, FALSE), "GENERAL")) | H46: =IF(B46="","",IFERROR(VLOOKUP(B46, PLANTA_BASE!A:R, 17, FALSE), "GENERAL"))
A47: =IF(B47="","",IFERROR(VLOOKUP(B47, PLANTA_BASE!A:R, 2, FALSE), "NO ENCONTRADO EN PLANTA")) | C47: =IF(B47="","",IFERROR(VLOOKUP(B47, PLANTA_BASE!A:R, 3, FALSE), "")) | D47: =IF(B47="","",IFERROR(VLOOKUP(B47, PLANTA_BASE!A:R, 5, FALSE), "NO ENCONTRADO EN PLANTA")) | E47: =IF(B47="","",IFERROR(VLOOKUP(B47, PLANTA_BASE!A:R, 6, FALSE), "NO ENCONTRADO EN PLANTA")) | F47: =IF(B47="","",IFERROR(VLOOKUP(B47, PLANTA_BASE!A:R, 8, FALSE), "DOCENTE / FACILITADOR")) | G47: =IF(B47="","",IFERROR(VLOOKUP(B47, PLANTA_BASE!A:R, 9, FALSE), "GENERAL")) | H47: =IF(B47="","",IFERROR(VLOOKUP(B47, PLANTA_BASE!A:R, 17, FALSE), "GENERAL"))
A48: =IF(B48="","",IFERROR(VLOOKUP(B48, PLANTA_BASE!A:R, 2, FALSE), "NO ENCONTRADO EN PLANTA")) | C48: =IF(B48="","",IFERROR(VLOOKUP(B48, PLANTA_BASE!A:R, 3, FALSE), "")) | D48: =IF(B48="","",IFERROR(VLOOKUP(B48, PLANTA_BASE!A:R, 5, FALSE), "NO ENCONTRADO EN PLANTA")) | E48: =IF(B48="","",IFERROR(VLOOKUP(B48, PLANTA_BASE!A:R, 6, FALSE), "NO ENCONTRADO EN PLANTA")) | F48: =IF(B48="","",IFERROR(VLOOKUP(B48, PLANTA_BASE!A:R, 8, FALSE), "DOCENTE / FACILITADOR")) | G48: =IF(B48="","",IFERROR(VLOOKUP(B48, PLANTA_BASE!A:R, 9, FALSE), "GENERAL")) | H48: =IF(B48="","",IFERROR(VLOOKUP(B48, PLANTA_BASE!A:R, 17, FALSE), "GENERAL"))
A49: =IF(B49="","",IFERROR(VLOOKUP(B49, PLANTA_BASE!A:R, 2, FALSE), "NO ENCONTRADO EN PLANTA")) | C49: =IF(B49="","",IFERROR(VLOOKUP(B49, PLANTA_BASE!A:R, 3, FALSE), "")) | D49: =IF(B49="","",IFERROR(VLOOKUP(B49, PLANTA_BASE!A:R, 5, FALSE), "NO ENCONTRADO EN PLANTA")) | E49: =IF(B49="","",IFERROR(VLOOKUP(B49, PLANTA_BASE!A:R, 6, FALSE), "NO ENCONTRADO EN PLANTA")) | F49: =IF(B49="","",IFERROR(VLOOKUP(B49, PLANTA_BASE!A:R, 8, FALSE), "DOCENTE / FACILITADOR")) | G49: =IF(B49="","",IFERROR(VLOOKUP(B49, PLANTA_BASE!A:R, 9, FALSE), "GENERAL")) | H49: =IF(B49="","",IFERROR(VLOOKUP(B49, PLANTA_BASE!A:R, 17, FALSE), "GENERAL"))
A50: =IF(B50="","",IFERROR(VLOOKUP(B50, PLANTA_BASE!A:R, 2, FALSE), "NO ENCONTRADO EN PLANTA")) | C50: =IF(B50="","",IFERROR(VLOOKUP(B50, PLANTA_BASE!A:R, 3, FALSE), "")) | D50: =IF(B50="","",IFERROR(VLOOKUP(B50, PLANTA_BASE!A:R, 5, FALSE), "NO ENCONTRADO EN PLANTA")) | E50: =IF(B50="","",IFERROR(VLOOKUP(B50, PLANTA_BASE!A:R, 6, FALSE), "NO ENCONTRADO EN PLANTA")) | F50: =IF(B50="","",IFERROR(VLOOKUP(B50, PLANTA_BASE!A:R, 8, FALSE), "DOCENTE / FACILITADOR")) | G50: =IF(B50="","",IFERROR(VLOOKUP(B50, PLANTA_BASE!A:R, 9, FALSE), "GENERAL")) | H50: =IF(B50="","",IFERROR(VLOOKUP(B50, PLANTA_BASE!A:R, 17, FALSE), "GENERAL"))
A51: =IF(B51="","",IFERROR(VLOOKUP(B51, PLANTA_BASE!A:R, 2, FALSE), "NO ENCONTRADO EN PLANTA")) | C51: =IF(B51="","",IFERROR(VLOOKUP(B51, PLANTA_BASE!A:R, 3, FALSE), "")) | D51: =IF(B51="","",IFERROR(VLOOKUP(B51, PLANTA_BASE!A:R, 5, FALSE), "NO ENCONTRADO EN PLANTA")) | E51: =IF(B51="","",IFERROR(VLOOKUP(B51, PLANTA_BASE!A:R, 6, FALSE), "NO ENCONTRADO EN PLANTA")) | F51: =IF(B51="","",IFERROR(VLOOKUP(B51, PLANTA_BASE!A:R, 8, FALSE), "DOCENTE / FACILITADOR")) | G51: =IF(B51="","",IFERROR(VLOOKUP(B51, PLANTA_BASE!A:R, 9, FALSE), "GENERAL")) | H51: =IF(B51="","",IFERROR(VLOOKUP(B51, PLANTA_BASE!A:R, 17, FALSE), "GENERAL"))
A52: =IF(B52="","",IFERROR(VLOOKUP(B52, PLANTA_BASE!A:R, 2, FALSE), "NO ENCONTRADO EN PLANTA")) | C52: =IF(B52="","",IFERROR(VLOOKUP(B52, PLANTA_BASE!A:R, 3, FALSE), "")) | D52: =IF(B52="","",IFERROR(VLOOKUP(B52, PLANTA_BASE!A:R, 5, FALSE), "NO ENCONTRADO EN PLANTA")) | E52: =IF(B52="","",IFERROR(VLOOKUP(B52, PLANTA_BASE!A:R, 6, FALSE), "NO ENCONTRADO EN PLANTA")) | F52: =IF(B52="","",IFERROR(VLOOKUP(B52, PLANTA_BASE!A:R, 8, FALSE), "DOCENTE / FACILITADOR")) | G52: =IF(B52="","",IFERROR(VLOOKUP(B52, PLANTA_BASE!A:R, 9, FALSE), "GENERAL")) | H52: =IF(B52="","",IFERROR(VLOOKUP(B52, PLANTA_BASE!A:R, 17, FALSE), "GENERAL"))
A53: =IF(B53="","",IFERROR(VLOOKUP(B53, PLANTA_BASE!A:R, 2, FALSE), "NO ENCONTRADO EN PLANTA")) | C53: =IF(B53="","",IFERROR(VLOOKUP(B53, PLANTA_BASE!A:R, 3, FALSE), "")) | D53: =IF(B53="","",IFERROR(VLOOKUP(B53, PLANTA_BASE!A:R, 5, FALSE), "NO ENCONTRADO EN PLANTA")) | E53: =IF(B53="","",IFERROR(VLOOKUP(B53, PLANTA_BASE!A:R, 6, FALSE), "NO ENCONTRADO EN PLANTA")) | F53: =IF(B53="","",IFERROR(VLOOKUP(B53, PLANTA_BASE!A:R, 8, FALSE), "DOCENTE / FACILITADOR")) | G53: =IF(B53="","",IFERROR(VLOOKUP(B53, PLANTA_BASE!A:R, 9, FALSE), "GENERAL")) | H53: =IF(B53="","",IFERROR(VLOOKUP(B53, PLANTA_BASE!A:R, 17, FALSE), "GENERAL"))
A54: =IF(B54="","",IFERROR(VLOOKUP(B54, PLANTA_BASE!A:R, 2, FALSE), "NO ENCONTRADO EN PLANTA")) | C54: =IF(B54="","",IFERROR(VLOOKUP(B54, PLANTA_BASE!A:R, 3, FALSE), "")) | D54: =IF(B54="","",IFERROR(VLOOKUP(B54, PLANTA_BASE!A:R, 5, FALSE), "NO ENCONTRADO EN PLANTA")) | E54: =IF(B54="","",IFERROR(VLOOKUP(B54, PLANTA_BASE!A:R, 6, FALSE), "NO ENCONTRADO EN PLANTA")) | F54: =IF(B54="","",IFERROR(VLOOKUP(B54, PLANTA_BASE!A:R, 8, FALSE), "DOCENTE / FACILITADOR")) | G54: =IF(B54="","",IFERROR(VLOOKUP(B54, PLANTA_BASE!A:R, 9, FALSE), "GENERAL")) | H54: =IF(B54="","",IFERROR(VLOOKUP(B54, PLANTA_BASE!A:R, 17, FALSE), "GENERAL"))
... A1501: =IF(B1501="","",IFERROR(VLOOKUP(B1501, PLANTA_BASE!A:R, 2, FALSE), "NO ENCONTRADO EN PLANTA")) | C1501: =IF(B1501="","",IFERROR(VLOOKUP(B1501, PLANTA_BASE!A:R, 3, FALSE), "")) | D1501: =IF(B1501="","",IFERROR(VLOOKUP(B1501, PLANTA_BASE!A:R, 5, FALSE), "NO ENCONTRADO EN PLANTA")) | E1501: =IF(B1501="","",IFERROR(VLOOKUP(B1501, PLANTA_BASE!A:R, 6, FALSE), "NO ENCONTRADO EN PLANTA")) | F1501: =IF(B1501="","",IFERROR(VLOOKUP(B1501, PLANTA_BASE!A:R, 8, FALSE), "DOCENTE / FACILITADOR")) | G1501: =IF(B1501="","",IFERROR(VLOOKUP(B1501, PLANTA_BASE!A:R, 9, FALSE), "GENERAL")) | H1501: =IF(B1501="","",IFERROR(VLOOKUP(B1501, PLANTA_BASE!A:R, 17, FALSE), "GENERAL"))

Sheet PLANTA_BASE
A1: CEDULA | B1: INVITACIÓN | C1: NOMBRE COMPLETO | D1: Nombre Nivel 1 | E1: Nombre Nivel 2 | F1: Nombre Nivel 3 | G1: Modalidad | H1: Descripción Cargo | I1: Nombre Centro Costo | J1: STATUS | K1: RESPONSABLE | L1: ESTADO DE CONFIRMACIÓN | M1: NOVEDAD | N1: Telefono | O1: Correo Personal | P1: Nombre Área | Q1: ESCUELA | R1: SALÓN
A2: 11225681 | B2: PRESENCIAL BOGOTÁ | C2: CAMILO ANDRES PACHECO ZAMBRANO | D2: OPERACIONES | E2: REGIONAL BOGOTA | F2: BOGOTA CENTRO | G2: PRESENCIAL | H2: DOCENTE AUX/N/TC/ADM EMP/FUN.ACADE-ADMIN | I2: ADMINISTRACION DE EMPRESAS | J2: NUEVO | K2: ALEXANDRA BUITRAGO | L2: CONFIRMADO PRESENCIAL | N2: 3213586136 | O2: CAMILOEYM@GMAIL.COM | P2: BTA SEDE A | Q2: TRANSFORMACIÓN EMPRESARIAL | R2: 300
A3: 1023945301 | B3: PRESENCIAL BOGOTÁ | C3: ANGIE TATIANA BECERRA NIETO | D3: OPERACIONES | E3: REGIONAL BOGOTA | F3: BOGOTA CENTRO | G3: PRESENCIAL | H3: DOC AUX T&T/N/MT/ADM EM | I3: ADMINISTRACION DE EMPRESAS | J3: NUEVO | K3: ALEXANDRA BUITRAGO | L3: CONFIRMADO PRESENCIAL | N3: 3244840645 | O3: ATBECERRAN@GMAIL.COM | P3: BTA SEDE A | Q3: TRANSFORMACIÓN EMPRESARIAL | R3: 300
A4: 1130640640 | B4: VIRTUAL | C4: MONICA ALEJANDRA PRADO LEYVA | D4: OPERACIONES | E4: REGIONAL VALLE DELCAUCA | F4: CALI | G4: VIRTUAL | H4: DOC AUX/N/V/TC/ADMIN PUBLICA/PROYECCION SO | I4: ADMINISTRACION PUBLICA | J4: NUEVO | K4: ALEXANDRA BUITRAGO | L4: CONFIRMADO VIRTUAL | N4: 3162546617 | O4: FINANCIERO.ESTRUCTURADO@GMAIL.COM | P4: CALI | Q4: NEGOCIOS
A5: 1022403253 | B5: PRESENCIAL BOGOTÁ | C5: DANIEL MATEO MOSQUERA LAGUNA | D5: OPERACIONES | E5: REGIONAL BOGOTA | F5: BOGOTA CENTRO | G5: PRESENCIAL | H5: DOC AUX T&T/N/MT/CIEN BASI | I5: CIENCIAS BASICAS | J5: NUEVO | K5: ALEXANDRA BUITRAGO | N5: 3102303667 | O5: MATEO.254@GMAIL.COM | P5: BTA SEDE A | Q5: TRANSVERSALES | R5: 700
A6: 1193247659 | B6: PRESENCIAL BOGOTÁ | C6: ERICK CAMILO TORRES RODRIGUEZ | D6: OPERACIONES | E6: REGIONAL BOGOTA | F6: BOGOTA CENTRO | G6: PRESENCIAL | H6: DOCENTE AUX/N/MT/CIEN BASI | I6: CIENCIAS BASICAS | J6: NUEVO | K6: ALEXANDRA BUITRAGO | N6: 3223671342 | O6: CAMILOTORR1@GMAIL.COM | P6: BTA SEDE A | Q6: TRANSVERSALES | R6: 700
A7: 92532543 | B7: PRESENCIAL REGIONAL | C7: CRISTIAN ALFONSO PACHECO PACHECO | D7: OPERACIONES | E7: REGIONAL SUCRE | F7: SINCELEJO | G7: PRESENCIAL | H7: DOCENTE AUX/N/MT/CIEN BASI | I7: CIENCIAS BASICAS | J7: NUEVO | K7: ALEXANDRA BUITRAGO | N7: 3058652076 | O7: CRISSPACHECO.MATEMATICO@GMAIL.COM | P7: SINCELEJO SEDE | Q7: TRANSVERSALES
A8: 1036626269 | B8: PRESENCIAL REGIONAL | C8: SEBASTIAN VALENCIA ALVAREZ | D8: OPERACIONES | E8: REGIONAL ANTIOQUIA | F8: MEDELLIN | G8: VIRTUAL | H8: DOC AUX T&T/N/V/TC/COMU SOC Y PERI/FUN.ACADE-ADMIN | I8: COMUNICACION SOCIAL Y PERIODISMO | J8: NUEVO | K8: ALEXANDRA BUITRAGO | N8: 3136109898 | O8: SEBASTIANVALENCIA89@GMAIL.COM | P8: MEDELLIN SEDE | Q8: BELLAS ARTES
A9: 80109407 | B9: PRESENCIAL BOGOTÁ | C9: ALEJANDRO ACOSTA CIFUENTES | D9: OPERACIONES | E9: REGIONAL BOGOTA | F9: BOGOTA CENTRO | G9: PRESENCIAL | H9: DOC AUX T&T/N/TC/COM SOC Y PER/FUN.ACADE-ADMIN | I9: COMUNICACION SOCIAL Y PERIODISMO | J9: NUEVO | K9: ALEXANDRA BUITRAGO | N9: 3188832167 | O9: ALEJANDROCOMUNICADOR@YAHOO.COM | P9: BTA SEDE A | Q9: BELLAS ARTES | R9: 303
A10: 1143861791 | B10: VIRTUAL | C10: NATHALIA ANDREA MARTINEZ IJAJI | D10: OPERACIONES | E10: REGIONAL VALLE DELCAUCA | F10: CALI | G10: VIRTUAL | H10: DOC AUX T&T/N/V/TC/COMU SOC Y PERI/FUN.ACADE-ADMIN | I10: COMUNICACION SOCIAL Y PERIODISMO | J10: NUEVO | K10: ALEXANDRA BUITRAGO | N10: 3005505057 | O10: NATHALIA18.MI@GMAIL.COM | P10: CALI | Q10: BELLAS ARTES
A11: 1023899660 | B11: PRESENCIAL BOGOTÁ | C11: JYNA PAOLA HOYOS HERNANDEZ | D11: OPERACIONES | E11: REGIONAL BOGOTA | F11: BOGOTA CENTRO | G11: PRESENCIAL | H11: DOCENTE ASIS/N/TC/COM SOC Y PER/FUN.ACADE-ADMIN | I11: COMUNICACION SOCIAL Y PERIODISMO | J11: NUEVO | K11: ALEXANDRA BUITRAGO | N11: 3208236273 | O11: HOYOSJINA92@GMAIL.COM | P11: BTA SEDE A | Q11: BELLAS ARTES | R11: 303
A12: 1091595049 | B12: PRESENCIAL BOGOTÁ | C12: NELSON SAMUEL GALVIS TORRES | D12: OPERACIONES | E12: REGIONAL BOGOTA | F12: BOGOTA CENTRO | G12: PRESENCIAL | H12: DOC AUX T&T/N/TC/COM SOC Y PER/FUN.ACADE-ADMIN | I12: COMUNICACION SOCIAL Y PERIODISMO | J12: NUEVO | K12: ALEXANDRA BUITRAGO | N12: 3173791675 | O12: NELSONSAMUELGALVIS@GMAIL.COM | P12: BTA SEDE A | Q12: BELLAS ARTES | R12: 303
A13: 1013628967 | B13: PRESENCIAL BOGOTÁ | C13: EDWARD LEONARDO QUINTERO AMAYA | D13: OPERACIONES | E13: REGIONAL BOGOTA | F13: BOGOTA CENTRO | G13: PRESENCIAL | H13: DOC AUX T&T/N/TC/COM SOC Y PER/FUN.ACADE-ADMIN | I13: COMUNICACION SOCIAL Y PERIODISMO | J13: NUEVO | K13: ALEXANDRA BUITRAGO | N13: 3208522598 | O13: LEOQUINTAMAYA@GMAIL.COM | P13: BTA SEDE A | Q13: BELLAS ARTES | R13: 303
A14: 1075227142 | B14: PRESENCIAL REGIONAL | C14: ANDRES FELIPE ARIAS IBAÑEZ | D14: OPERACIONES | E14: REGIONAL HUILA | F14: NEIVA | G14: PRESENCIAL | H14: DOC AUX T&T/N/TC/COM SOC Y PER/FUN.ACADE-ADMIN | I14: COMUNICACION SOCIAL Y PERIODISMO | J14: NUEVO | K14: ALEXANDRA BUITRAGO | N14: 3225133913 | O14: ANDRARIB02@GMAIL.COM | P14: NEIVA SEDE | Q14: BELLAS ARTES
A15: 1007475970 | B15: PRESENCIAL BOGOTÁ | C15: JULIAN MATEO RODRIGUEZ SIERRA | D15: OPERACIONES | E15: REGIONAL BOGOTA | F15: BOGOTA CENTRO | G15: PRESENCIAL | H15: DOC AUX T&T/N/TC/COM SOC Y PER/FUN.ACADE-ADMIN | I15: COMUNICACION SOCIAL Y PERIODISMO | J15: NUEVO | K15: ALEXANDRA BUITRAGO | N15: 3507895820 | O15: JULIMATEO@GMAIL.COM | P15: BTA SEDE A | Q15: BELLAS ARTES | R15: 303
A16: 52288882 | B16: PRESENCIAL BOGOTÁ | C16: DIANA MILENA AVILA MARTINEZ | D16: OPERACIONES | E16: REGIONAL BOGOTA | F16: BOGOTA CENTRO | G16: VIRTUAL | H16: DOC AUX T&T/N/V/MT/CONTADURIA | I16: CONTADURIA PUBLICA | J16: NUEVO | K16: ALEXANDRA BUITRAGO | N16: 3196436917 | O16: DIANA.DIANAMILENAAVILAMARTINEZ@GMAIL.COM | P16: BTA SEDE A | Q16: NEGOCIOS | R16: 200
A17: 52027093 | B17: PRESENCIAL BOGOTÁ | C17: SONIA PATRICIA TORRES CORTES | D17: OPERACIONES | E17: REGIONAL BOGOTA | F17: BOGOTA CENTRO | G17: VIRTUAL | H17: DOC ASIS/N/V/MT/CONTADURIA | I17: CONTADURIA PUBLICA | J17: NUEVO | K17: ALEXANDRA BUITRAGO | N17: 310 3415572 | O17: SONIAPATRICIATORRESCORTES@YAHOO.COM | P17: BTA SEDE A | Q17: NEGOCIOS | R17: 200
A18: 1070959485 | B18: PRESENCIAL BOGOTÁ | C18: ANGIE PAOLA DUEÑAS MORA | D18: OPERACIONES | E18: REGIONAL BOGOTA | F18: BOGOTA CENTRO | G18: VIRTUAL | H18: DOC ASIS/N/V/MT/CONTADURIA | I18: CONTADURIA PUBLICA | J18: NUEVO | K18: ALEXANDRA BUITRAGO | N18: 3239695165 | O18: ANGIE.DUENAS@EST.UEXTERNADO.EDU.CO | P18: BTA SEDE A | Q18: NEGOCIOS | R18: 200
A19: 79948014 | B19: PRESENCIAL BOGOTÁ | C19: NELSON ANDRES CAMARGO GUILLOMBO | D19: OPERACIONES | E19: REGIONAL BOGOTA | F19: BOGOTA CENTRO | G19: VIRTUAL | H19: DOC AUX/N/V/MT/CONTADURIA | I19: CONTADURIA PUBLICA | J19: NUEVO | K19: ALEXANDRA BUITRAGO | N19: 3218913990 | O19: NELSONANDRESCAMARGOG45@GMAIL.COM | P19: BTA SEDE A | Q19: NEGOCIOS | R19: 200
A20: 1013651517 | B20: PRESENCIAL BOGOTÁ | C20: NICOLAS BERMUDEZ ROJAS | D20: OPERACIONES | E20: REGIONAL BOGOTA | F20: BOGOTA CENTRO | G20: VIRTUAL | H20: DOC AUX/N/V/MT/CONTADURIA | I20: CONTADURIA PUBLICA | J20: NUEVO | K20: ALEXANDRA BUITRAGO | N20: 3158921950 | O20: NICONTABLE15@GMAIL.COM | P20: BTA SEDE A | Q20: NEGOCIOS | R20: 200
A21: 79818033 | B21: PRESENCIAL BOGOTÁ | C21: CARLOS ARTURO RIAÑO AMAYA | D21: OPERACIONES | E21: REGIONAL BOGOTA | F21: BOGOTA CENTRO | G21: VIRTUAL | H21: DOC AUX/N/V/MT/CONTADURIA | I21: CONTADURIA PUBLICA | J21: NUEVO | K21: ALEXANDRA BUITRAGO | N21: 3005960501 | O21: RIANOACA@JAVERIANA.EDU.CO | P21: BTA SEDE A | Q21: NEGOCIOS | R21: 200
A22: 28551871 | B22: PRESENCIAL REGIONAL | C22: LADY CAROLINA MORENO ROJAS | D22: OPERACIONES | E22: REGIONAL TOLIMA | F22: IBAGUÉ | G22: VIRTUAL | H22: DOC AUX/N/V/MT/CONTADURIA | I22: CONTADURIA PUBLICA | J22: NUEVO | K22: ALEXANDRA BUITRAGO | N22: 3052489288 | O22: LADYCAROLINAMORENOROJAS@GMAIL.COM | P22: IBAGUE SEDE | Q22: NEGOCIOS
A23: 15444486 | B23: PRESENCIAL REGIONAL | C23: JUAN FERNANDO CARDONA VERGARA | D23: OPERACIONES | E23: REGIONAL ANTIOQUIA | F23: MEDELLIN | G23: VIRTUAL | H23: DOC ASIS/N/V/TC/DIR PROD ME AUD/FUN.ACA | I23: DIRECCION Y PRODUCCION DE MEDIOS AUDIOVISUALES | J23: NUEVO | K23: ALEXANDRA BUITRAGO | N23: 3156651916 | O23: ZETTACO@GMAIL.COM | P23: MEDELLIN SEDE | Q23: BELLAS ARTES
A24: 1001198453 | B24: PRESENCIAL BOGOTÁ | C24: DIANA MARCELA GARCIA DIAZ | D24: OPERACIONES | E24: REGIONAL BOGOTA | F24: BOGOTA CENTRO | G24: PRESENCIAL | H24: DOC AUX T&T/N/MT/DIS EXP INT | I24: DISEÑO EXPERIENCIAS INTERACTIVAS | J24: NUEVO | K24: ALEXANDRA BUITRAGO | N24: 3208081766 | O24: DIGARCIA1815@GMAIL.COM | P24: BTA SEDE A | Q24: BELLAS ARTES | R24: 303
A25: 80794905 | B25: PRESENCIAL BOGOTÁ | C25: MIGUEL ANGEL ACOSTA SANABRIA | D25: OPERACIONES | E25: REGIONAL BOGOTA | F25: BOGOTA CENTRO | G25: PRESENCIAL | H25: DOCENTE ASIS/N/MT/DIS GRAFICO | I25: DISEÑO GRAFICO | J25: NUEVO | K25: ALEXANDRA BUITRAGO | N25: 3182760847 | O25: MIGUELACOSTA28@ME.COM | P25: BTA SEDE A | Q25: BELLAS ARTES | R25: 303
A26: 79962408 | B26: PRESENCIAL BOGOTÁ | C26: MANUEL ALEJANDRO RODRIGUEZ ROJAS | D26: OPERACIONES | E26: REGIONAL BOGOTA | F26: BOGOTA CENTRO | G26: PRESENCIAL | H26: DOCENTE AUX/N/TC/EMPRENDIMIE/FUN.ACADE-ADMIN | I26: EMPRENDIMIENTO | J26: NUEVO | K26: ALEXANDRA BUITRAGO | N26: 3502692135 | O26: PSALEJANDRO2507@GMAIL.COM | P26: BTA SEDE A | Q26: TRANSVERSALES | R26: 700
A27: 1030587886 | B27: PRESENCIAL BOGOTÁ | C27: GUSTAVO ADOLFO RUBIANO JIMENEZ | D27: OPERACIONES | E27: REGIONAL BOGOTA | F27: BOGOTA CENTRO | G27: PRESENCIAL | H27: DOCENTE AUX/N/TC/EMPRENDIMIE/FUN.ACADE-ADMIN | I27: EMPRENDIMIENTO | J27: NUEVO | K27: ALEXANDRA BUITRAGO | N27: 3184130782 | O27: G.RUBIANO2502@GMAIL.COM | P27: BTA SEDE A | Q27: TRANSVERSALES | R27: 700
A28: 79949138 | B28: PRESENCIAL BOGOTÁ | C28: DAVID GUERRERO FERNANDEZ | D28: OPERACIONES | E28: REGIONAL BOGOTA | F28: BOGOTA CENTRO | G28: PRESENCIAL | H28: DOC AUX T&T/N/TC/EMPRENDIMIE/FUN.ACADE-ADMIN | I28: EMPRENDIMIENTO | J28: NUEVO | K28: ALEXANDRA BUITRAGO | L28: CONFIRMADO PRESENCIAL | N28: 3014376415 | O28: D_GUERRE@YAHOO.COM | P28: BTA SEDE A | Q28: TRANSVERSALES | R28: 700
A29: 1030539124 | B29: PRESENCIAL BOGOTÁ | C29: LADY JOHANNA HUERTAS RAMIREZ | D29: OPERACIONES | E29: REGIONAL BOGOTA | F29: BOGOTA CENTRO | G29: PRESENCIAL | H29: DOCENTE AUX/N/TC/EMPRENDIMIE/FUN.ACADE-ADMIN | I29: EMPRENDIMIENTO | J29: NUEVO | K29: ALEXANDRA BUITRAGO | N29: 3168253361 | O29: LADYJOHANNA22@GMAIL.COM | P29: BTA SEDE A | Q29: TRANSVERSALES | R29: 700
A30: 1010221623 | B30: PRESENCIAL BOGOTÁ | C30: OSCAR IVAN MAYORGA ROMERO | D30: OPERACIONES | E30: REGIONAL BOGOTA | F30: BOGOTA CENTRO | G30: PRESENCIAL | H30: DOCENTE AUX/N/TC/EMPRENDIMIE/FUN.ACADE-ADMIN | I30: EMPRENDIMIENTO | J30: NUEVO | K30: ALEXANDRA BUITRAGO | N30: 3508563870 | O30: OSCAR.697@HOTMAIL.COM | P30: BTA SEDE A | Q30: TRANSVERSALES | R30: 700
A31: 1016040558 | B31: PRESENCIAL BOGOTÁ | C31: ANDRES FELIPE RAMIREZ ACEVEDO | D31: OPERACIONES | E31: REGIONAL BOGOTA | F31: BOGOTA CENTRO | G31: PRESENCIAL | H31: DOC AUX T&T/N/TC/EMPRENDIMIE/FUN.ACADE-ADMIN | I31: EMPRENDIMIENTO | J31: NUEVO | K31: ALEXANDRA BUITRAGO | L31: CONFIRMADO PRESENCIAL | N31: 3194950805 | O31: TIENDAIKWA@GMAIL.COM | P31: BTA SEDE A | Q31: TRANSVERSALES | R31: 700
A32: 1031139139 | B32: PRESENCIAL BOGOTÁ | C32: CATHERINE YISEL PARRA VIA | D32: OPERACIONES | E32: REGIONAL BOGOTA | F32: BOGOTA CENTRO | G32: PRESENCIAL | H32: DOC AUX T&T/N/TC/EMPRENDIMIE/FUN.ACADE-ADMIN | I32: EMPRENDIMIENTO | J32: NUEVO | K32: ALEXANDRA BUITRAGO | N32: 3043908759 | O32: YISEL2107.1910@GMAIL.COM | P32: BTA SEDE A | Q32: TRANSVERSALES | R32: 700
A33: 52998146 | B33: PRESENCIAL BOGOTÁ | C33: ELIZABETH MERCEDES BERNAL MARTINEZ | D33: OPERACIONES | E33: REGIONAL BOGOTA | F33: BOGOTA CENTRO | G33: PRESENCIAL | H33: DOCENTE ASIS/N/TC/EMPRENDIMIE/FUN.ACADE-ADMIN | I33: EMPRENDIMIENTO | J33: NUEVO | K33: ALEXANDRA BUITRAGO | N33: 3105552183 | O33: ELIZABETH.M.BERNAL@GMAIL.COM | P33: BTA SEDE A | Q33: TRANSVERSALES | R33: 700
A34: 1130670364 | B34: PRESENCIAL BOGOTÁ | C34: JUAN PABLO ALBAN PERDOMO | D34: OPERACIONES | E34: REGIONAL BOGOTA | F34: BOGOTA CENTRO | G34: PRESENCIAL | H34: DOCENTE AUX/N/TC/EMPRENDIMIE/FUN.ACADE-ADMIN | I34: EMPRENDIMIENTO | J34: NUEVO | K34: ALEXANDRA BUITRAGO | N34: 3013904886 | O34: JUANALBAN47@GMAIL.COM | P34: BTA SEDE A | Q34: TRANSVERSALES | R34: 700
A35: 1102853205 | B35: PRESENCIAL BOGOTÁ | C35: JESUS DAVID TUIRAN RUIZ | D35: OPERACIONES | E35: REGIONAL BOGOTA | F35: BOGOTA CENTRO | G35: VIRTUAL | H35: DOC ASIS/N/V/TC/ESP CONTRA ESTATAL/FUN.A | I35: ESPECIALIZACION DE CONTRATACION ESTATAL | J35: NUEVO | K35: ALEXANDRA BUITRAGO | L35: CONFIRMADO PRESENCIAL | N35: 3016649496 | O35: JESUSDAVIDTUIRANRUIZ@GMAIL.COM | P35: BTA SEDE A | Q35: ESPECIALIZACIONES | R35: 602
A36: 1010179348 | B36: PRESENCIAL BOGOTÁ | C36: JUAN CAMILO CAMACHO OSORIO | D36: OPERACIONES | E36: REGIONAL BOGOTA | F36: BOGOTA CENTRO | G36: VIRTUAL | H36: DOC ASIS/N/V/TC/ESP CONTRA ESTATAL/FUN.A | I36: ESPECIALIZACION DE CONTRATACION ESTATAL | J36: NUEVO | K36: ALEXANDRA BUITRAGO | N36: 3124619087 | O36: JUANC.CAMACHOO@GMAIL.COM | P36: BTA SEDE A | Q36: ESPECIALIZACIONES | R36: 602
A37: 1015465318 | B37: PRESENCIAL BOGOTÁ | C37: MATEO MANCERA CAMACHO | D37: OPERACIONES | E37: REGIONAL BOGOTA | F37: BOGOTA CENTRO | G37: VIRTUAL | H37: DOC AUX T&T/N/V/TC/ESP DYD VIDEOJUEGOS/F | I37: ESPECIALIZACION DISEÑO Y DESARROLLO VIDEOJUEGOS | J37: NUEVO | K37: ALEXANDRA BUITRAGO | N37: 3193963095 | O37: MATEO.M.CAMACHO@HOTMAIL.ES | P37: BTA SEDE A | Q37: ESPECIALIZACIONES | R37: 602
A38: 1085319934 | B38: VIRTUAL | C38: OSWALDO ANDRES ORDOÑEZ BOLAÑOS | D38: OPERACIONES | E38: REGIONAL NARIÑO | F38: PASTO | G38: VIRTUAL | H38: DOC ASIS/N/V/TC/ESP DYD VIDEOJUEGOS/FUN. | I38: ESPECIALIZACION DISEÑO Y DESARROLLO VIDEOJUEGOS | J38: NUEVO | K38: ALEXANDRA BUITRAGO | N38: 3157191848 | O38: OSWALDORDONEZ@UNICAUCA.EDU.CO | P38: PASTO SEDE | Q38: ESPECIALIZACIONES
A39: 1015460105 | B39: PRESENCIAL BOGOTÁ | C39: SERGIO GOMEZ DELGADO | D39: OPERACIONES | E39: REGIONAL BOGOTA | F39: BOGOTA CENTRO | G39: VIRTUAL | H39: DOC AUX T&T/N/V/TC/ESP DYD VIDEOJUEGOS/F | I39: ESPECIALIZACION DISEÑO Y DESARROLLO VIDEOJUEGOS | J39: NUEVO | K39: ALEXANDRA BUITRAGO | N39: 3197377015 | O39: SERGIOMLP123@HOTMAIL.COM | P39: BTA SEDE A | Q39: ESPECIALIZACIONES | R39: 602
A40: 1047438711 | B40: VIRTUAL | C40: LUIS GUILLERMO LOZANO PEÑARANDA | D40: OPERACIONES | E40: REGIONAL BOLIVAR | F40: CARTAGENA | G40: VIRTUAL | H40: DOC AUX/N/V/TC/ESP CIBERSEG/FUN.ACA | I40: ESPECIALIZACION EN CIBERSEGURIDAD | J40: NUEVO | K40: ALEXANDRA BUITRAGO | L40: CONFIRMADO VIRTUAL | N40: 3027913380 | O40: LUISLOZANOP@OUTLOOK.COM | P40: CARTAGENA SEDE | Q40: ESPECIALIZACIONES
...

Sheet Resumen_y_Graficos
A1: RESUMEN EJECUTIVO DE ASISTENCIA CUN
A3: Modalidad / Invitación | B3: Cantidad Registros
A4: PRESENCIAL BOGOTA | B4: 373
A5: PRESENCIAL REGIONAL | B5: 5
A6: VIRTUAL | B6: 1
A7: TOTAL GENERAL | B7: =SUM(B4:B6)
A10: Regional (Nombre Nivel 2) | B10: Presenciales
A11: REGIONAL BOGOTA | B11: 370
A12: REGIONAL CUNDINAMARCA | B12: 3
A13: REGIONAL HUILA | B13: 2
A14: REGIONAL CORDOBA | B14: 1
A15: REGIONAL ANTIOQUIA | B15: 1
A16: REGIONAL TOLIMA | B16: 1
